SampleOutputSPSC/sample_vwap_6.txt
XBUY: 16.5865
NRGX: 20.4516
CFG-D: 24.9331
ZYNE: 5.0674
ZYME: 15.3608
ZXZZT: 6.6666
ZWZZT: 4.8333
ZVZZT: 9.9895
ZUO: 21.2555
ZUMZ: 25.1102
ZTS: 85.2794
ZTR: 9.7628
ZTO: 17.0208
ZSL: 34.8844
ZSAN: 2.2661
ZS: 45.4676
ZROZ: 74.7242
ZOM: 0.6443
ZNWAA: 1.5066
ZNH: 32.9738
ZNGA: 4.479
ZN: 0.481
ZMLP: 9.0533
ZLAB: 26.8951
ZKIN: 1.55
ZJZZT: 6.6666
ZIXI: 7.4872
ZIV: 66.7966
ZIOP: 2.069
ZION: 48.3404
ZGNX: 41.7257
ZG: 32.9541
ZFGN: 4.2384
ZF: 8.7571
ZEUS: 18.6827
ZEN: 65.3672
ZEAL: 14.2007
ZDGE: 1.2933
ZBRA: 171.1648
ZBIO: 15.9084
ZBH: 107.549
ZB-G: 22.61
ZAYO: 26.7182
ZAGG: 11.2203
Z: 33.2423
YYY: 16.542
YY: 67.1592
YXI: 19.3333
YUMC: 35.7589
YUMA: 0.1133
YUM: 93.2184
YTRA: 5.1028
YTEN: 0.7726
YRIV: 2.073
YRD: 10.9871
YRCW: 5.8116
YPF: 15.8121
YORW: 31.1513
YOGA: 0.5282
YNDX: 33.0744
YMLP: 19.35
YMLI: 8.2466
YMAB: 19.6867
YLDE: 3.6192
YLCO: 12.33
YINN: 21.7288
YIN: 6.9976
YI: 8.9863
YGYI: 7.3249
YEXT: 14.9856
YETI: 16.7833
YELP: 36.1856
YCS: 61.8867
YANG: 52.1043
Y: 623.3385
XYL: 70.9148
XYF: 5.36
XXII: 2.287
XWEB: 84.7414
XTN: 39.7815
XTL: 65.0421
XT: 35.6906
XSW: 75.9357
XSPA: 0.1816
XSOE: 25.7025
XSLV: 45.7805
XSD: 69.6236
XRX: 27.8556
XRT: 44.0142
XRLV: 22.7399
XRAY: 41.2616
XPP: 65.7765
XPO: 61.5623
XPH: 38.5133
XPER: 21.1357
XOP: 30.6268
XONE: 8.4128
XON: 7.5294
XOMA: 12.0206
XOM: 71.98
XOG: 4.0775
XNTK: 52.752
XNET: 3.4062
XNCR: 32.485
XMLV: 45.557
XME: 30.1298
XLY: 107.2018
XLV: 88.9669
XLU: 53.4968
XLRN: 40.2218
XLRE: 33.9397
XLP: 52.2841
XLNX: 111.4527
XLK: 65.7974
XLI: 71.1144
XLG: 187.2396
XLF: 25.9697
XLE: 63.0125
XLC: 43.9078
XLB: 53.9759
XKST: 26.5
XITK: 92.5633
XINA: 0.7866
XIN: 4.7641
XHS: 30.7221
XHR: 18.6336
XHE: 71.8581
XHB: 35.717
XGTI: 0.3695
XFLT: 8.4626
XES: 10.9142
XERS: 14.9501
XENT: 29.0012
XENE: 8.0475
XELB: 1.25
XELA: 3.6007
XEL: 50.9604
XEC: 75.8731
XCEM: 17.2466
XBIT: 6.4476
XBIO: 2.1132
XBI: 80.7598
XAR: 88.681
XAN-C: 24.9933
XAN: 10.5114
X: 22.2285
WYY: 0.4399
WYNN: 119.9336
WYND: 42.365
WY: 26.126
WWW: 33.9273
WWR: 0.1433
WWE: 82.4341
WWD: 85.929
WVE: 35.5806
WUBA: 61.1806
WU: 18.2693
WTW: 31.8157
WTTR: 8.5927
WTT: 31.1666
WTS: 73.2986
WTRH: 12.1393
WTR: 34.2874
WTMF: 25.5999
WTM: 892.0455
WTIU: 13.7796
WTID: 9.7636
WTI: 5.0709
WTFCM: 26.99
WTFC: 72.5592
WTER: 3.5003
WTBA: 21.5941
WSTL: 1.7854
WST: 105.558
WSR: 14.2428
WSO: 146.0898
WSM: 52.5121
WSFS: 42.0458
WSC: 10.1286
WSBF: 16.857
WSBC: 41.5507
WRTC: 2.6397
WRN: 0.7288
WRLSR: 0.2539
WRLS: 6.7999
WRLD: 110.4663
WRK: 41.3464
WRI: 28.4339
WRE: 25.1606
WRD: 17.1855
WRB-E: 23.9759
WRB-D: 16.4116
WRB-C: 25.2104
WRB-B: 24.5272
WRB: 76.9949
WPX: 12.275
WPS: 36.6051
WPRT: 1.4798
WPP: 57.7072
WPM: 20.3652
WPG-I: 10.1866
WPG-H: 10.4999
WPG: 5.7641
WPC: 73.9461
WP: 84.0834
WOW: 7.2433
WOR: 36.8218
WOOD: 66.233
WNS: 48.9136
WNEB: 9.2823
WNC: 13.9836
WMT: 94.8945
WMS: 24.9996
WMK: 47.8044
WMGIZ: 0.0046
WMGI: 29.784
WMC: 9.5903
WMB: 26.8979
WM: 94.6044
WLTW: 160.263
WLL: 28.8063
WLKP: 18.9935
WLK: 76.1483
WLH: 30.2592
WLFC: 34.5177
WLDN: 33.4051
WKHS: 0.8852
WK: 39.2848
WIX: 105.7643
WIW: 10.0573
WIT: 5.4864
WISA: 3.2423
WIRE: 52.3386
WIP: 35.9212
WINS: 22.4786
WING: 66.1186
WINA: 152.1071
WIN: 2.8623
WILC: 5.4266
WIL: 42.9666
WIFI: 22.8963
WIA: 10.9305
WHR: 131.0423
WHLRW: 0.0068
WHLRP: 10.2934
WHLRD: 11.8366
WHLR: 1.6784
WHLM: 3.4999
WHG: 29.9994
WHF: 13.6765
WHD: 32.4038
WH: 49.6627
WGP: 32.6712
WGO: 29.3969
WFT: 0.6427
WFHY: 32.9333
WFE-A: 24.3099
WFC-Y: 24.6365
WFC-X: 22.3759
WFC-W: 23.5535
WFC-V: 25.8144
WFC-T: 17.1933
WFC-R: 18.4815
WFC-Q: 20.9374
WFC-P: 20.3304
WFC-O: 23.0381
WFC-N: 21.9436
WFC-L: 862.4133
WFC: 50.0032
WEYS: 27.2287
WEX: 157.6821
WETF: 6.5021
WES: 49.8977
WERN: 33.1818
WEN: 17.3229
WELL-I: 67.3824
WELL: 76.5687
WEC: 71.0766
WEBK: 19.7333
WEAT: 6.027
WEA: 12.5025
WDRW: 30.5955
WDR: 16.8386
WDIV: 65.36
WDFC: 178.242
WDC: 43.0485
WDAY: 169.8672
WD: 47.898
WCN: 81.4014
WCHN: 16.8933
WCG: 275.322
WCC: 53.6369
WBT: 13.8411
WBS-F: 19.0788
WBS: 55.9441
WBK: 18.2493
WBIY: 15.8999
WBIR: 15.4666
WBII: 16.1399
WBIH: 21.9714
WBIG: 15.5599
WBID: 20.95
WBIB: 21.24
WBC: 113.0611
WBAI: 14.3018
WBA: 71.6461
WB: 58.3098
WATT: 7.3504
WAT: 230.3952
WASH: 51.69
WAL: 45.546
WAIR: 8.0979
WAGE: 30.8139
WAFD: 29.2101
WABC: 62.9462
WAB: 68.5088
WAAS: 20.9769
W: 107.5891
VZA: 25.3286
VZ: 53.3108
VYMI: 59.6813
VYM: 81.7736
VYGR: 10.4851
VXZB: 20.0749
VXXB: 37.8703
VXUS: 50.5044
VXRT: 1.6672
VXF: 109.6275
VWOB: 75.1341
VWO: 40.928
VVV: 22.3848
VVUS: 4.717
VVR: 3.7918
VVI: 51.8404
VVC: 72.2765
VV: 122.4926
VUZI: 4.0321
VUSE: 28.7751
VUG: 143.866
VTWV: 89.4055
VTWO: 117.909
VTWG: 133.4195
VTVT: 2.7213
VTV: 103.6191
VTSI: 3.8781
VTR: 63.9012
VTNR: 1.3168
VTN: 12.6228
VTL: 0.195
VTIQU: 6.8666
VTIP: 48.0913
VTI: 136.7553
VTHR: 118.2332
VTGN: 1.5308
VTEB: 51.0982
VTC: 72.6316
VTA: 10.6977
VT: 69.9197
VSTO: 10.3239
VSTM: 3.1239
VST: 24.9036
VSS: 100.7612
VSMV: 28.0687
VSM: 37.0917
VSLR: 4.0121
VSI: 4.5797
VSH: 19.1471
VSGX: 31.8266
VSEC: 32.1811
VSAT: 61.4174
VRTX: 186.0696
VRTV: 33.227
VRTU: 47.7438
VRTSP: 76.3837
VRTS: 87.2201
VRSN: 166.1161
VRSK: 117.3028
VRS: 24.7106
VRRM: 10.2725
VRP: 22.5843
VRNT: 47.1044
VRNS: 57.4899
VRNA: 5.4944
VRML: 0.6858
VRIG: 17.8434
VREX: 27.9794
VRCA: 11.9686
VRAY: 6.9229
VRA: 8.9473
VPV: 12.0451
VPU: 119.6404
VPL: 64.5433
VPG: 32.0248
VOYA: 45.9437
VOXX: 5.1845
VOX: 78.341
VOT: 131.0206
VOOV: 105.0515
VOOG: 141.5742
VOO: 244.5301
VONV: 103.7421
VONG: 143.9348
VONE: 122.2192
VOE: 103.7219
VOD: 17.8482
VOC: 3.6181
VO: 151.3124
VNTR: 4.6473
VNRX: 2.5525
VNQI: 57.0893
VNQ: 82.4498
VNOM: 30.5246
VNO-M: 15.1533
VNO-L: 21.3263
VNO: 68.6654
VNM: 15.7882
VNLA: 49.344
VNET: 8.7071
VNE: 29.2834
VNDA: 28.2968
VNCE: 11.6927
VMW: 146.0488
VMOT: 16.7666
VMO: 11.6548
VMM: 12.17
VMI: 126.6817
VMC: 101.5742
VMBS: 51.6806
VLYPP: 24.7849
VLYPO: 23.6395
VLY: 10.2985
VLUE: 78.1149
VLT: 13.7657
VLRX: 0.3978
VLRS: 7.4241
VLO: 82.5338
VLGEA: 25.6924
VKTXW: 2.4921
VKTX: 8.0888
VKQ: 11.7635
VKI: 8.9508
VJET: 1.3866
VIXY: 31.1205
VIXM: 22.4469
VIVO: 16.0788
VIVE: 1.1822
VIV: 12.9504
VISI: 2.4666
VIS: 126.8717
VIRT: 25.4484
VIRC: 4.0118
VIPS: 7.4747
VIOV: 116.4129
VIOT: 7.4066
VIOO: 135.2443
VIOG: 99.6338
VIIX: 15.7806
VIGI: 60.8694
VIG: 103.2739
VIDI: 21.9055
VICR: 40.2754
VICL: 0.962
VICI: 21.4665
VIAV: 10.7769
VIAB: 28.4381
VIA: 32.8244
VHT: 166.961
VHI: 3.2828
VHC: 4.9551
VGZ: 0.6454
VGT: 178.1878
VGSH: 60.1444
VGR: 10.5375
VGM: 11.5283
VGLT: 74.3061
VGK: 51.7636
VGIT: 63.4184
VGI: 11.1809
VG: 9.0406
VFMV: 52.5599
VFMF: 48.2733
VFH: 65.0196
VFC: 84.1536
VEU: 48.6626
VET: 24.0692
VERU: 1.4914
VERI: 5.4363
VER-F: 20.0661
VER: 8.0199
VEON: 2.4637
VEGI: 18.8058
VEEV: 107.2719
VEDL: 11.1338
VECO: 9.8274
VEC: 24.2788
VEACW: 0.4367
VEAC: 10.1332
VEA: 39.6787
VDE: 85.1836
VDC: 135.6773
VCYT: 17.5554
VCV: 10.9481
VCTR: 10.5724
VCSH: 78.6928
VCRA: 39.8207
VCR: 163.3495
VCLT: 87.3191
VCIT: 84.4696
VCF: 9.1999
VCEL: 35.9576
VC: 75.4044
VBTX: 26.4659
VBR: 126.0891
VBND: 47.5914
VBLT: 1.3022
VBK: 166.7754
VBIV: 1.6408
VBF: 17.6067
VB: 145.555
VAW: 119.574
VAR: 131.5563
VAPO: 16.4759
VAM: 20.7266
VALU: 20.5132
VALQ: 25.1869
VALE: 12.3854
VAC: 87.5608
V: 136.5027
UZC: 16.618
UZB: 22.2055
UZA: 24.5266
UYM: 36.3466
UYG: 36.4513
UXIN: 3.4645
UWT: 14.145
UWN: 2.3824
UWM: 62.967
UVXY: 58.3749
UVV: 57.4701
UVSP: 23.7615
UVE: 37.7837
UUUU+: 0.8666
UUUU: 2.8898
UUU: 1.1875
UUP: 25.4639
UTX: 118.7636
UTSL: 26.7456
UTSI: 3.4011
UTMD: 88.8296
UTL: 48.4983
UTI: 3.3777
UTHR: 115.771
UTG: 29.856
UTF: 22.9868
UTES: 22.8799
USX: 7.4087
USWSW: 0.67
USWS: 7.6243
USVM: 28.9003
UST: 36.9599
USRT: 46.4453
USPH: 106.2543
USOU: 25.7497
USOI: 21.63
USOD: 6.5686
USO: 11.4173
USNA: 115.7279
USMV: 54.7446
USMF: 18.5133
USM: 56.0261
USLV: 80.4322
USLB: 29.4694
USL: 13.9053
USIG: 53.7137
USHY: 31.822
USG: 43.1243
USFR: 24.4339
USFD: 34.2768
USEQ: 17.4266
USEG: 0.8873
USDU: 25.6373
USDP: 10.7507
USD: 30.9053
USCR: 37.3942
USCI: 33.0308
USB-P: 24.2318
USB-O: 23.2511
USB-M: 25.8996
USB-H: 19.4214
USB: 51.1025
USAU: 0.9971
USAT: 5.685
USAS: 1.6035
USAP: 17.8146
USAK: 18.4682
USAC: 15.119
USA: 5.7479
URTY: 64.7722
URTH: 81.5259
UROV: 8.8669
