SampleOutputSPSC/sample_vwap_7.txt
XBUY: 16.5865
NRGX: 20.3783
CFG-D: 24.9535
ZYNE: 5.0714
ZYME: 15.3706
ZXZZT: 6.6666
ZWZZT: 4.8333
ZVZZT: 9.9906
ZUO: 21.276
ZUMZ: 25.1622
ZTS: 85.2771
ZTR: 9.7814
ZTO: 17.0635
ZSL: 34.8506
ZSAN: 2.2755
ZS: 45.4752
ZROZ: 87.8509
ZOM: 0.7687
ZNWAA: 1.5066
ZNH: 34.1479
ZNGA: 4.4798
ZN: 0.4823
ZMLP: 9.0533
ZLAB: 26.8928
ZKIN: 1.55
ZJZZT: 6.6666
ZIXI: 7.4373
ZIV: 66.8254
ZIOP: 2.0815
ZION: 48.2841
ZHOK: 62.24
ZGNX: 42.0687
ZG: 33.0977
ZFGN: 4.2498
ZF: 8.7571
ZEUS: 18.7258
ZEN: 65.5404
ZEAL: 14.1962
ZDGE: 1.2933
ZBRA: 171.313
ZBIO: 15.881
ZBH: 107.9574
ZB-H: 16.8499
ZB-G: 22.051
ZAYO: 26.723
ZAGG: 11.2362
Z: 33.3823
YYY: 17.065
YY: 67.3143
YXI: 19.3333
YVR: 2.4833
YUMC: 35.7936
YUMA: 0.1133
YUM: 93.2548
YTRA: 5.102
YTEN: 0.8172
YRIV: 2.073
YRD: 10.9868
YRCW: 5.8382
YPF: 15.8247
YORW: 32.224
YOGA: 0.5282
YNDX: 33.2654
YMLP: 19.35
YMLI: 8.2466
YMAB: 19.7729
YLDE: 3.6192
YLCO: 12.33
YINN: 21.7944
YIN: 6.9996
YI: 9.005
YGYI: 7.2991
YEXT: 15.0456
YETI: 16.7907
YELP: 36.2295
YCS: 61.8867
YAO: 20.1333
YANG: 51.841
Y: 623.6311
XYL: 71.3078
XYF: 5.3974
XXII: 2.2967
XWEB: 82.2619
XTN: 39.7815
XTL: 65.0421
XT: 35.7342
XSW: 79.3428
XSPA: 0.1822
XSOE: 27.1775
XSLV: 45.8279
XSD: 69.8576
XRX: 27.9101
XRT: 44.0373
XRLV: 22.7399
XRAY: 41.4254
XPP: 65.7765
XPO: 61.6576
XPH: 38.516
XPER: 21.1646
XOP: 30.7157
XONE: 8.4332
XON: 7.6018
XOMA: 12.0417
XOM: 72.0734
XOG: 4.0949
XNTK: 61.4135
XNET: 3.4072
XNCR: 32.4928
XMLV: 45.8922
XME: 30.1945
XLY: 107.3302
XLV: 89.0774
XLU: 53.5285
XLRN: 40.9234
XLRE: 33.9567
XLP: 52.306
XLNX: 111.9154
XLK: 65.915
XLI: 71.1929
XLG: 187.5585
XLF: 25.9761
XLE: 63.0868
XLC: 44.0239
XLB: 54.0352
XKST: 26.5
XITK: 92.5633
XINA: 0.7866
XIN: 4.7648
XHS: 30.7221
XHR: 18.6283
XHE: 72.6913
XHB: 35.7905
XGTI: 0.3682
XFLT: 8.4626
XES: 10.9566
XERS: 14.9041
XENT: 29.1133
XENE: 8.0612
XELB: 1.2513
XELA: 3.597
XEL: 50.9833
XEC: 75.9679
XCEM: 17.2466
XBIT: 6.4478
XBIO: 2.1033
XBI: 81.1667
XAR: 88.8063
XAN-C: 21.6015
XAN: 10.5034
X: 22.2584
WYY: 0.4343
WYNN: 120.1396
WYND: 42.4502
WY: 26.1501
WWW: 33.9694
WWR: 0.1487
WWE: 82.6305
WWD: 86.087
WVE: 35.7065
WUBA: 61.277
WU: 18.2818
WTW: 31.7105
WTTR: 8.6074
WTT: 30.7689
WTS: 73.5983
WTRH: 12.1384
WTR: 34.315
WTMF: 25.5999
WTM: 891.6478
WTIU: 13.6861
WTID: 9.7636
WTI: 5.0884
WTFCM: 27.4086
WTFC: 72.3915
WTER: 3.4924
WTBA: 21.5831
WSTL: 1.7751
WSTG: 7.0733
WST: 105.7145
WSR: 14.2235
WSO: 145.9449
WSM: 52.6307
WSFS: 42.0732
WSC: 10.1691
WSBF: 16.7862
WSBC: 41.5877
WRTC: 2.935
WRN: 0.7257
WRLSW: 0.1675
WRLSR: 0.2554
WRLS: 6.7999
WRLD: 110.8937
WRK: 41.3896
WRI: 28.4649
WRE: 25.1697
WRD: 17.2405
WRB-E: 23.9759
WRB-D: 22.1202
WRB-C: 24.7317
WRB-B: 25.2802
WRB: 77.0229
WPX: 12.2902
WPS: 36.6051
WPRT: 1.4806
WPP: 57.7153
WPM: 20.3973
WPG-I: 10.1866
WPG-H: 15.6979
WPG: 5.7588
WPC: 73.9921
WP: 84.4413
WOW: 7.238
WOR: 37.1083
WOOD: 66.2528
WNS: 48.8946
WNEB: 9.2832
WNC: 13.9972
WMT: 94.8942
WMS: 24.9627
WMK: 48.0321
WMGIZ: 0.0046
WMGI: 29.8363
WMC: 9.5841
WMB: 26.9423
WM: 94.6846
WLTW: 160.5267
WLL: 28.9357
WLKP: 20.5818
WLK: 76.3867
WLH: 25.6884
WLFC: 36.4478
WLDN: 33.4122
WKHS: 0.8832
WK: 39.3126
WIX: 106.2554
WIW: 10.1848
WIT: 5.494
WISA: 3.2432
WIRE: 52.488
WIP: 35.9524
WINS: 22.4786
WING: 66.1111
WINA: 153.2487
WIN: 2.867
WILC: 5.4266
WIL: 42.9666
WIFI: 23.137
WIA: 10.738
WHR: 131.2571
WHLRW: 0.0068
WHLRP: 10.2934
WHLRD: 11.8366
WHLR: 1.6895
WHLM: 5.7191
WHG: 30.9807
WHFBZ: 16.9999
WHF: 13.6935
WHD: 32.4328
WH: 49.617
WGP: 32.7342
WGO: 29.5472
WFT: 0.6413
WFHY: 32.9333
WFE-A: 24.3099
WFC-Y: 24.6365
WFC-X: 22.7781
WFC-W: 24.0964
WFC-V: 25.8164
WFC-T: 22.7477
WFC-R: 23.4464
WFC-Q: 21.3761
WFC-P: 19.5758
WFC-O: 23.0463
WFC-N: 21.9436
WFC-L: 862.4133
WFC: 50.0346
WEYS: 27.219
WEX: 158.3095
WETF: 6.5184
WES: 50.0591
WERN: 33.3189
WEN: 17.3288
WELL-I: 67.4323
WELL: 76.5787
WEC: 71.1737
WEBK: 19.8433
WEAT: 6.027
WEA: 12.2092
WDRW: 30.5781
WDR: 16.8414
WDIV: 65.36
WDFC: 178.0949
WDC: 43.2706
WDAY: 170.8716
WD: 47.934
WCN: 82.0903
WCHN: 16.8933
WCG: 275.5135
WCC: 53.883
WBT: 13.8399
WBS-F: 19.0788
WBS: 55.6114
WBK: 18.2858
WBIY: 15.8999
WBIR: 15.4666
WBII: 16.1399
WBIH: 21.9714
WBIG: 15.5599
WBID: 20.95
WBIB: 21.24
WBC: 113.1836
WBAI: 14.3885
WBA: 71.6634
WB: 58.442
WATT: 7.365
WAT: 230.7274
WASH: 51.6282
WAL: 45.446
WAIR: 8.1039
WAGE: 30.8528
WAFD: 29.2367
WABC: 62.827
WAB: 68.4733
WAAS: 20.9357
W: 107.6797
VZA: 25.3286
VZ: 53.4499
VYMI: 59.7532
VYM: 81.8816
VYGR: 10.4752
VXZB: 19.6425
VXXB: 37.6837
VXUS: 50.6117
VXRT: 1.6672
VXF: 109.8255
VWOB: 75.2188
VWO: 41.0061
VVV: 22.3997
VVUS: 4.7186
VVR: 3.8386
VVI: 52.1655
VVC: 72.2947
VV: 122.6968
VUZI: 4.0295
VUSE: 28.7751
VUG: 144.0666
VTWV: 89.4055
VTWO: 117.9664
VTWG: 128.2324
VTVT: 2.7462
VTV: 104.0385
VTSI: 3.8843
VTR: 63.9019
VTNR: 1.3161
VTN: 12.6204
VTL: 0.1959
VTIQU: 6.8666
VTIP: 48.1013
VTI: 136.9419
VTHR: 115.1877
VTGN: 1.5341
VTEB: 51.1055
VTC: 72.6316
VTA: 10.6992
VT: 70.0541
VSTO: 10.3107
VSTM: 3.1709
VST: 24.9191
VSS: 100.9149
VSMV: 28.0687
VSM: 37.2368
VSLR: 4.0149
VSI: 4.5869
VSH: 19.2271
VSGX: 37.8613
VSEC: 32.2047
VSAT: 61.4321
VRTX: 186.4323
VRTV: 33.3593
VRTU: 47.9737
VRTSP: 76.3837
VRTS: 87.3273
VRSN: 166.6237
VRSK: 117.5278
VRS: 24.707
VRRM: 10.283
VRP: 22.8194
VRNT: 47.4126
VRNS: 57.5044
VRNA: 5.4944
VRML: 0.6858
VRIG: 17.8424
VREX: 27.9857
VRCA: 11.9765
VRAY: 6.9225
VRA: 8.9517
VPV: 12.0651
VPU: 119.7059
VPL: 64.6676
VPG: 32.3144
VOYA: 46.0237
VOXX: 5.2132
VOX: 78.4543
VOT: 131.1366
VOOV: 105.0895
VOOG: 142.2491
VOO: 245.2383
VONV: 103.8321
VONG: 144.1752
VONE: 122.35
VOE: 103.8241
VOD: 17.875
VOC: 3.7467
VO: 151.3632
VNTR: 4.7173
VNRX: 2.5571
VNQI: 57.1434
VNQ: 82.483
VNOM: 30.6862
VNO-M: 15.1533
VNO-L: 20.8605
VNO: 68.7098
VNM: 15.8
VNLA: 49.344
VNET: 8.7103
VNE: 29.3439
VNDA: 28.2095
VNCE: 11.6927
VMW: 146.2539
VMOT: 16.7608
VMO: 11.6672
VMM: 12.17
VMI: 126.9667
VMC: 101.4293
VMBS: 51.7045
VLYPP: 24.803
VLYPO: 23.6558
VLY: 10.3442
VLUE: 78.2545
VLT: 13.7657
VLRX: 0.3977
VLRS: 7.4229
VLO: 82.7106
VLGEA: 26.0157
VKTXW: 2.4921
VKTX: 8.1754
VKQ: 11.7714
VKI: 10.0855
VJET: 1.3916
VIXY: 30.9886
VIXM: 22.0681
VIVO: 16.1167
VIVE: 1.1761
VIV: 12.9786
VISI: 2.4666
VIS: 129.5872
VIRT: 25.4081
VIRC: 3.8651
VIPS: 7.4805
VIOV: 115.7816
VIOT: 7.4992
VIOO: 137.2049
VIOG: 136.3031
VIIX: 15.7364
VIGI: 61.0642
VIG: 103.3966
VIDI: 24.4104
VICR: 40.3047
VICL: 0.9714
VICI: 21.4515
VIAV: 10.7943
VIAB: 28.4985
VIA: 32.9451
VHT: 167.2608
VHI: 3.2864
VHC: 5.0151
VGZ: 0.6519
VGT: 178.6797
VGSH: 60.1471
VGR: 10.5578
VGM: 11.7521
VGLT: 74.3181
VGK: 51.7964
VGIT: 63.4925
VGI: 11.0562
VG: 9.0468
VFMV: 75.473
VFMO: 49.1466
VFMF: 48.6265
VFLQ: 50.7866
VFH: 65.0492
VFC: 84.2986
VEU: 48.7304
VET: 24.1285
VERU: 1.4909
VERI: 5.4499
VER-F: 20.0661
VER: 8.0167
VEON: 2.4642
VEGI: 18.8058
VEEV: 107.6544
VEDL: 11.1436
VECO: 9.8284
VEC: 24.3386
VEACW: 0.4367
VEAC: 10.1314
VEA: 39.7096
VDE: 85.1952
VDC: 135.6987
VCYT: 17.5636
VCV: 11.0578
VCTR: 10.5779
VCSH: 78.7235
VCRA: 39.8515
VCR: 163.5569
VCNX: 3.3999
VCLT: 87.3637
VCIT: 84.5265
VCF: 9.1999
VCEL: 28.8376
VC: 75.9571
VBTX: 26.507
VBR: 126.1991
VBND: 47.7905
VBLT: 1.2984
VBK: 167.1681
VBIV: 1.6394
VBFC: 23.2333
VBF: 17.6091
VB: 145.6988
VAW: 119.7296
VAR: 131.9218
VAPO: 16.4734
VAMO: 14.8333
VAM: 20.7266
VALU: 21.1897
VALQ: 25.1869
VALE: 12.4161
VAC: 87.6748
V: 136.8211
UZC: 16.618
UZB: 22.2055
UZA: 24.5266
UYM: 36.3466
UYG: 37.0483
UXIN: 3.4515
UWT: 14.1426
UWN: 2.4115
UWM: 62.9808
UVXY: 57.9298
UVV: 57.7943
UVSP: 23.7255
UVE: 37.7936
UUUU+: 0.8666
UUUU: 2.8884
UUU: 1.1875
UUP: 25.4592
UTX: 118.8998
UTSL: 26.9347
UTSI: 3.2483
UTMD: 92.4974
UTL: 48.7504
UTI: 3.3651
UTHR: 115.9126
UTG: 29.4428
UTF: 22.9938
UTES: 22.8799
USX: 7.4679
USWSW: 0.67
USWS: 7.6641
USVM: 28.9003
UST: 54.6062
USRT: 46.6592
USPH: 106.2875
USOU: 25.7497
USOI: 21.63
USOD: 5.2835
USO: 11.4163
USNA: 115.527
USMV: 54.8043
USMF: 18.5912
USM: 56.0332
USLV: 80.6563
USLM: 46.5266
USLB: 29.4694
USL: 13.9051
USIG: 53.7493
USHY: 31.822
USG: 43.1272
USFR: 24.8732
USFD: 34.2301
USEQ: 17.4266
USEG: 0.8869
USDU: 24.7626
USDP: 10.9478
USD: 31.2874
USCR: 37.449
USCI: 33.0492
USB-P: 23.1223
USB-O: 23.2511
